Workbook

Sheet Title page

Sheet Acknowledgements

Sheet Instructions

Sheet Data sheet
A1: Hours | B1: Days | D1: Phototherapy | E1: Exchange Transfusion | I1: >= 38 wks phototherapy | J1: >= 38 wks exchange
A2: 0 | B2: 0 | C2: =A2/24 -> 0 | D2: =IF(AND('Treatment threshold graphs'!$M$6>=22,'Treatment threshold graphs'!$M$6<=37),40,'Data sheet'!I2) -> 100 | E2: =IF(AND('Treatment threshold graphs'!$M$6>=22,'Treatment threshold graphs'!$M$6<=37),80,'Data sheet'!J2) -> 100 | I2: 100 | J2: 100
A3: 6 | C3: =A3/24 -> 0.25 | D3: =IF(AND('Treatment threshold graphs'!$M$6>=22,'Treatment threshold graphs'!$M$6<=37),D2+(($D$15-$D$2)/12),'Data sheet'!I3) -> 125 | E3: =IF(AND('Treatment threshold graphs'!$M$6>=22,'Treatment threshold graphs'!$M$6<=37),E2+(($E$14-$E$2)/12),'Data sheet'!J3) -> 150 | I3: 125 | J3: 150
A4: 12 | C4: =A4/24 -> 0.5 | D4: =IF(AND('Treatment threshold graphs'!$M$6>=22,'Treatment threshold graphs'!$M$6<=37),D3+(($D$15-$D$2)/12),'Data sheet'!I4) -> 150 | E4: =IF(AND('Treatment threshold graphs'!$M$6>=22,'Treatment threshold graphs'!$M$6<=37),E3+(($E$14-$E$2)/12),'Data sheet'!J4) -> 200 | I4: 150 | J4: 200
A5: 18 | C5: =A5/24 -> 0.75 | D5: =IF(AND('Treatment threshold graphs'!$M$6>=22,'Treatment threshold graphs'!$M$6<=37),D4+(($D$15-$D$2)/12),'Data sheet'!I5) -> 175 | E5: =IF(AND('Treatment threshold graphs'!$M$6>=22,'Treatment threshold graphs'!$M$6<=37),E4+(($E$14-$E$2)/12),'Data sheet'!J5) -> 250 | I5: 175 | J5: 250
A6: 24 | B6: 1 | C6: =A6/24 -> 1 | D6: =IF(AND('Treatment threshold graphs'!$M$6>=22,'Treatment threshold graphs'!$M$6<=37),D5+(($D$15-$D$2)/12),'Data sheet'!I6) -> 200 | E6: =IF(AND('Treatment threshold graphs'!$M$6>=22,'Treatment threshold graphs'!$M$6<=37),E5+(($E$14-$E$2)/12),'Data sheet'!J6) -> 300 | I6: 200 | J6: 300
A7: 30 | C7: =A7/24 -> 1.25 | D7: =IF(AND('Treatment threshold graphs'!$M$6>=22,'Treatment threshold graphs'!$M$6<=37),D6+(($D$15-$D$2)/12),'Data sheet'!I7) -> 212 | E7: =IF(AND('Treatment threshold graphs'!$M$6>=22,'Treatment threshold graphs'!$M$6<=37),E6+(($E$14-$E$2)/12),'Data sheet'!J7) -> 350 | I7: 212 | J7: 350
A8: 36 | C8: =A8/24 -> 1.5 | D8: =IF(AND('Treatment threshold graphs'!$M$6>=22,'Treatment threshold graphs'!$M$6<=37),D7+(($D$15-$D$2)/12),'Data sheet'!I8) -> 225 | E8: =IF(AND('Treatment threshold graphs'!$M$6>=22,'Treatment threshold graphs'!$M$6<=37),E7+(($E$14-$E$2)/12),'Data sheet'!J8) -> 400 | I8: 225 | J8: 400
A9: 42 | C9: =A9/24 -> 1.75 | D9: =IF(AND('Treatment threshold graphs'!$M$6>=22,'Treatment threshold graphs'!$M$6<=37),D8+(($D$15-$D$2)/12),'Data sheet'!I9) -> 237 | E9: =IF(AND('Treatment threshold graphs'!$M$6>=22,'Treatment threshold graphs'!$M$6<=37),E8+(($E$14-$E$2)/12),'Data sheet'!J9) -> 450 | I9: 237 | J9: 450
A10: 48 | B10: 2 | C10: =A10/24 -> 2 | D10: =IF(AND('Treatment threshold graphs'!$M$6>=22,'Treatment threshold graphs'!$M$6<=37),D9+(($D$15-$D$2)/12),'Data sheet'!I10) -> 250 | E10: =IF(AND('Treatment threshold graphs'!$M$6>=22,'Treatment threshold graphs'!$M$6<=37),E9+(($E$14-$E$2)/12),'Data sheet'!J10) -> 450 | I10: 250 | J10: 450
A11: 54 | C11: =A11/24 -> 2.25 | D11: =IF(AND('Treatment threshold graphs'!$M$6>=22,'Treatment threshold graphs'!$M$6<=37),D10+(($D$15-$D$2)/12),'Data sheet'!I11) -> 262 | E11: =IF(AND('Treatment threshold graphs'!$M$6>=22,'Treatment threshold graphs'!$M$6<=37),E10+(($E$14-$E$2)/12),'Data sheet'!J11) -> 450 | I11: 262 | J11: 450
A12: 60 | C12: =A12/24 -> 2.5 | D12: =IF(AND('Treatment threshold graphs'!$M$6>=22,'Treatment threshold graphs'!$M$6<=37),D11+(($D$15-$D$2)/12),'Data sheet'!I12) -> 275 | E12: =IF(AND('Treatment threshold graphs'!$M$6>=22,'Treatment threshold graphs'!$M$6<=37),E11+(($E$14-$E$2)/12),'Data sheet'!J12) -> 450 | I12: 275 | J12: 450
A13: 66 | C13: =A13/24 -> 2.75 | D13: =IF(AND('Treatment threshold graphs'!$M$6>=22,'Treatment threshold graphs'!$M$6<=37),D12+(($D$15-$D$2)/12),'Data sheet'!I13) -> 287 | E13: =IF(AND('Treatment threshold graphs'!$M$6>=22,'Treatment threshold graphs'!$M$6<=37),E12+(($E$14-$E$2)/12),'Data sheet'!J13) -> 450 | I13: 287 | J13: 450
A14: 72 | B14: 3 | C14: =A14/24 -> 3 | D14: =IF(AND('Treatment threshold graphs'!$M$6>=22,'Treatment threshold graphs'!$M$6<=37),D13+(($D$15-$D$2)/12),'Data sheet'!I14) -> 300 | E14: =IF(AND('Treatment threshold graphs'!$M$6>=22,'Treatment threshold graphs'!$M$6<=37),'Treatment threshold graphs'!$M$6*10,'Data sheet'!J14) -> 450 | I14: 300 | J14: 450
A15: 78 | C15: =A15/24 -> 3.25 | D15: =IF(AND('Treatment threshold graphs'!$M$6>=22,'Treatment threshold graphs'!$M$6<=37),'Treatment threshold graphs'!$M$6*10-100,'Data sheet'!I15) -> 312 | E15: =IF(AND('Treatment threshold graphs'!$M$6>=22,'Treatment threshold graphs'!$M$6<=37),'Treatment threshold graphs'!$M$6*10,'Data sheet'!J15) -> 450 | I15: 312 | J15: 450
A16: 84 | C16: =A16/24 -> 3.5 | D16: =IF(AND('Treatment threshold graphs'!$M$6>=22,'Treatment threshold graphs'!$M$6<=37),'Treatment threshold graphs'!$M$6*10-100,'Data sheet'!I16) -> 325 | E16: =IF(AND('Treatment threshold graphs'!$M$6>=22,'Treatment threshold graphs'!$M$6<=37),'Treatment threshold graphs'!$M$6*10,'Data sheet'!J16) -> 450 | I16: 325 | J16: 450
A17: 90 | C17: =A17/24 -> 3.75 | D17: =IF(AND('Treatment threshold graphs'!$M$6>=22,'Treatment threshold graphs'!$M$6<=37),'Treatment threshold graphs'!$M$6*10-100,'Data sheet'!I17) -> 337 | E17: =IF(AND('Treatment threshold graphs'!$M$6>=22,'Treatment threshold graphs'!$M$6<=37),'Treatment threshold graphs'!$M$6*10,'Data sheet'!J17) -> 450 | I17: 337 | J17: 450
A18: 96 | B18: 4 | C18: =A18/24 -> 4 | D18: =IF(AND('Treatment threshold graphs'!$M$6>=22,'Treatment threshold graphs'!$M$6<=37),'Treatment threshold graphs'!$M$6*10-100,'Data sheet'!I18) -> 350 | E18: =IF(AND('Treatment threshold graphs'!$M$6>=22,'Treatment threshold graphs'!$M$6<=37),'Treatment threshold graphs'!$M$6*10,'Data sheet'!J18) -> 450 | I18: 350 | J18: 450
A19: 102 | C19: =A19/24 -> 4.25 | D19: =IF(AND('Treatment threshold graphs'!$M$6>=22,'Treatment threshold graphs'!$M$6<=37),'Treatment threshold graphs'!$M$6*10-100,'Data sheet'!I19) -> 350 | E19: =IF(AND('Treatment threshold graphs'!$M$6>=22,'Treatment threshold graphs'!$M$6<=37),'Treatment threshold graphs'!$M$6*10,'Data sheet'!J19) -> 450 | I19: 350 | J19: 450
A20: 108 | C20: =A20/24 -> 4.5 | D20: =IF(AND('Treatment threshold graphs'!$M$6>=22,'Treatment threshold graphs'!$M$6<=37),'Treatment threshold graphs'!$M$6*10-100,'Data sheet'!I20) -> 350 | E20: =IF(AND('Treatment threshold graphs'!$M$6>=22,'Treatment threshold graphs'!$M$6<=37),'Treatment threshold graphs'!$M$6*10,'Data sheet'!J20) -> 450 | I20: 350 | J20: 450
A21: 114 | C21: =A21/24 -> 4.75 | D21: =IF(AND('Treatment threshold graphs'!$M$6>=22,'Treatment threshold graphs'!$M$6<=37),'Treatment threshold graphs'!$M$6*10-100,'Data sheet'!I21) -> 350 | E21: =IF(AND('Treatment threshold graphs'!$M$6>=22,'Treatment threshold graphs'!$M$6<=37),'Treatment threshold graphs'!$M$6*10,'Data sheet'!J21) -> 450 | I21: 350 | J21: 450
A22: 120 | B22: 5 | C22: =A22/24 -> 5 | D22: =IF(AND('Treatment threshold graphs'!$M$6>=22,'Treatment threshold graphs'!$M$6<=37),'Treatment threshold graphs'!$M$6*10-100,'Data sheet'!I22) -> 350 | E22: =IF(AND('Treatment threshold graphs'!$M$6>=22,'Treatment threshold graphs'!$M$6<=37),'Treatment threshold graphs'!$M$6*10,'Data sheet'!J22) -> 450 | I22: 350 | J22: 450
A23: 126 | C23: =A23/24 -> 5.25 | D23: =IF(AND('Treatment threshold graphs'!$M$6>=22,'Treatment threshold graphs'!$M$6<=37),'Treatment threshold graphs'!$M$6*10-100,'Data sheet'!I23) -> 350 | E23: =IF(AND('Treatment threshold graphs'!$M$6>=22,'Treatment threshold graphs'!$M$6<=37),'Treatment threshold graphs'!$M$6*10,'Data sheet'!J23) -> 450 | I23: 350 | J23: 450
A24: 132 | C24: =A24/24 -> 5.5 | D24: =IF(AND('Treatment threshold graphs'!$M$6>=22,'Treatment threshold graphs'!$M$6<=37),'Treatment threshold graphs'!$M$6*10-100,'Data sheet'!I24) -> 350 | E24: =IF(AND('Treatment threshold graphs'!$M$6>=22,'Treatment threshold graphs'!$M$6<=37),'Treatment threshold graphs'!$M$6*10,'Data sheet'!J24) -> 450 | I24: 350 | J24: 450
A25: 138 | C25: =A25/24 -> 5.75 | D25: =IF(AND('Treatment threshold graphs'!$M$6>=22,'Treatment threshold graphs'!$M$6<=37),'Treatment threshold graphs'!$M$6*10-100,'Data sheet'!I25) -> 350 | E25: =IF(AND('Treatment threshold graphs'!$M$6>=22,'Treatment threshold graphs'!$M$6<=37),'Treatment threshold graphs'!$M$6*10,'Data sheet'!J25) -> 450 | I25: 350 | J25: 450
A26: 144 | B26: 6 | C26: =A26/24 -> 6 | D26: =IF(AND('Treatment threshold graphs'!$M$6>=22,'Treatment threshold graphs'!$M$6<=37),'Treatment threshold graphs'!$M$6*10-100,'Data sheet'!I26) -> 350 | E26: =IF(AND('Treatment threshold graphs'!$M$6>=22,'Treatment threshold graphs'!$M$6<=37),'Treatment threshold graphs'!$M$6*10,'Data sheet'!J26) -> 450 | I26: 350 | J26: 450
A27: 150 | C27: =A27/24 -> 6.25 | D27: =IF(AND('Treatment threshold graphs'!$M$6>=22,'Treatment threshold graphs'!$M$6<=37),'Treatment threshold graphs'!$M$6*10-100,'Data sheet'!I27) -> 350 | E27: =IF(AND('Treatment threshold graphs'!$M$6>=22,'Treatment threshold graphs'!$M$6<=37),'Treatment threshold graphs'!$M$6*10,'Data sheet'!J27) -> 450 | I27: 350 | J27: 450
A28: 156 | C28: =A28/24 -> 6.5 | D28: =IF(AND('Treatment threshold graphs'!$M$6>=22,'Treatment threshold graphs'!$M$6<=37),'Treatment threshold graphs'!$M$6*10-100,'Data sheet'!I28) -> 350 | E28: =IF(AND('Treatment threshold graphs'!$M$6>=22,'Treatment threshold graphs'!$M$6<=37),'Treatment threshold graphs'!$M$6*10,'Data sheet'!J28) -> 450 | I28: 350 | J28: 450
A29: 162 | C29: =A29/24 -> 6.75 | D29: =IF(AND('Treatment threshold graphs'!$M$6>=22,'Treatment threshold graphs'!$M$6<=37),'Treatment threshold graphs'!$M$6*10-100,'Data sheet'!I29) -> 350 | E29: =IF(AND('Treatment threshold graphs'!$M$6>=22,'Treatment threshold graphs'!$M$6<=37),'Treatment threshold graphs'!$M$6*10,'Data sheet'!J29) -> 450 | I29: 350 | J29: 450
A30: 168 | B30: 7 | C30: =A30/24 -> 7 | D30: =IF(AND('Treatment threshold graphs'!$M$6>=22,'Treatment threshold graphs'!$M$6<=37),'Treatment threshold graphs'!$M$6*10-100,'Data sheet'!I30) -> 350 | E30: =IF(AND('Treatment threshold graphs'!$M$6>=22,'Treatment threshold graphs'!$M$6<=37),'Treatment threshold graphs'!$M$6*10,'Data sheet'!J30) -> 450 | I30: 350 | J30: 450
A31: 174 | C31: =A31/24 -> 7.25 | D31: =IF(AND('Treatment threshold graphs'!$M$6>=22,'Treatment threshold graphs'!$M$6<=37),'Treatment threshold graphs'!$M$6*10-100,'Data sheet'!I31) -> 350 | E31: =IF(AND('Treatment threshold graphs'!$M$6>=22,'Treatment threshold graphs'!$M$6<=37),'Treatment threshold graphs'!$M$6*10,'Data sheet'!J31) -> 450 | I31: 350 | J31: 450
A32: 180 | C32: =A32/24 -> 7.5 | D32: =IF(AND('Treatment threshold graphs'!$M$6>=22,'Treatment threshold graphs'!$M$6<=37),'Treatment threshold graphs'!$M$6*10-100,'Data sheet'!I32) -> 350 | E32: =IF(AND('Treatment threshold graphs'!$M$6>=22,'Treatment threshold graphs'!$M$6<=37),'Treatment threshold graphs'!$M$6*10,'Data sheet'!J32) -> 450 | I32: 350 | J32: 450
A33: 186 | C33: =A33/24 -> 7.75 | D33: =IF(AND('Treatment threshold graphs'!$M$6>=22,'Treatment threshold graphs'!$M$6<=37),'Treatment threshold graphs'!$M$6*10-100,'Data sheet'!I33) -> 350 | E33: =IF(AND('Treatment threshold graphs'!$M$6>=22,'Treatment threshold graphs'!$M$6<=37),'Treatment threshold graphs'!$M$6*10,'Data sheet'!J33) -> 450 | I33: 350 | J33: 450
A34: 192 | B34: 8 | C34: =A34/24 -> 8 | D34: =IF(AND('Treatment threshold graphs'!$M$6>=22,'Treatment threshold graphs'!$M$6<=37),'Treatment threshold graphs'!$M$6*10-100,'Data sheet'!I34) -> 350 | E34: =IF(AND('Treatment threshold graphs'!$M$6>=22,'Treatment threshold graphs'!$M$6<=37),'Treatment threshold graphs'!$M$6*10,'Data sheet'!J34) -> 450 | I34: 350 | J34: 450
A35: 198 | C35: =A35/24 -> 8.25 | D35: =IF(AND('Treatment threshold graphs'!$M$6>=22,'Treatment threshold graphs'!$M$6<=37),'Treatment threshold graphs'!$M$6*10-100,'Data sheet'!I35) -> 350 | E35: =IF(AND('Treatment threshold graphs'!$M$6>=22,'Treatment threshold graphs'!$M$6<=37),'Treatment threshold graphs'!$M$6*10,'Data sheet'!J35) -> 450 | I35: 350 | J35: 450
A36: 204 | C36: =A36/24 -> 8.5 | D36: =IF(AND('Treatment threshold graphs'!$M$6>=22,'Treatment threshold graphs'!$M$6<=37),'Treatment threshold graphs'!$M$6*10-100,'Data sheet'!I36) -> 350 | E36: =IF(AND('Treatment threshold graphs'!$M$6>=22,'Treatment threshold graphs'!$M$6<=37),'Treatment threshold graphs'!$M$6*10,'Data sheet'!J36) -> 450 | I36: 350 | J36: 450
A37: 210 | C37: =A37/24 -> 8.75 | D37: =IF(AND('Treatment threshold graphs'!$M$6>=22,'Treatment threshold graphs'!$M$6<=37),'Treatment threshold graphs'!$M$6*10-100,'Data sheet'!I37) -> 350 | E37: =IF(AND('Treatment threshold graphs'!$M$6>=22,'Treatment threshold graphs'!$M$6<=37),'Treatment threshold graphs'!$M$6*10,'Data sheet'!J37) -> 450 | I37: 350 | J37: 450
A38: 216 | B38: 9 | C38: =A38/24 -> 9 | D38: =IF(AND('Treatment threshold graphs'!$M$6>=22,'Treatment threshold graphs'!$M$6<=37),'Treatment threshold graphs'!$M$6*10-100,'Data sheet'!I38) -> 350 | E38: =IF(AND('Treatment threshold graphs'!$M$6>=22,'Treatment threshold graphs'!$M$6<=37),'Treatment threshold graphs'!$M$6*10,'Data sheet'!J38) -> 450 | I38: 350 | J38: 450
A39: 222 | C39: =A39/24 -> 9.25 | D39: =IF(AND('Treatment threshold graphs'!$M$6>=22,'Treatment threshold graphs'!$M$6<=37),'Treatment threshold graphs'!$M$6*10-100,'Data sheet'!I39) -> 350 | E39: =IF(AND('Treatment threshold graphs'!$M$6>=22,'Treatment threshold graphs'!$M$6<=37),'Treatment threshold graphs'!$M$6*10,'Data sheet'!J39) -> 450 | I39: 350 | J39: 450
A40: 228 | C40: =A40/24 -> 9.5 | D40: =IF(AND('Treatment threshold graphs'!$M$6>=22,'Treatment threshold graphs'!$M$6<=37),'Treatment threshold graphs'!$M$6*10-100,'Data sheet'!I40) -> 350 | E40: =IF(AND('Treatment threshold graphs'!$M$6>=22,'Treatment threshold graphs'!$M$6<=37),'Treatment threshold graphs'!$M$6*10,'Data sheet'!J40) -> 450 | I40: 350 | J40: 450
...

Sheet Treatment threshold graphs
E1: Treatment threshold graph for babies with neonatal jaundice
A2: Baby's name | H2: Date of birth
A4: Hospital number | E4: Time of birth | H4: Direct Antiglobulin Test
M5: Click below and choose gestation
A6: Shade for phototherapy | D6: Baby's blood group | H6: Mother's blood group | M6: >=38 | N6: weeks gestation

Sheet Where to find the guidance
